<?xml version="1.0"?>
<robot xmlns:xacro="http://www.ros.org/wiki/xacro">
  <!-- Solid-box inertia helper -->
  <xacro:macro name="box_inertia" params="m x y z">
    <inertial>
      <mass value="${m}"/>
      <inertia
        ixx="${(1.0/12.0)*m*(y*y + z*z)}" ixy="0.0" ixz="0.0"
        iyy="${(1.0/12.0)*m*(x*x + z*z)}" iyz="0.0"
        izz="${(1.0/12.0)*m*(x*x + y*y)}"/>
    </inertial>
  </xacro:macro>

  <xacro:macro name="buddy_base">
    <link name="base_footprint"/>

    <joint name="base_footprint_joint" type="fixed">
      <parent link="base_footprint"/>
      <child link="base_link"/>
      <origin xyz="0 0 ${base_center_z}" rpy="0 0 0"/>
    </joint>

    <link name="base_link">
      <visual>
        <geometry><box size="${base_length} ${base_width} ${base_height}"/></geometry>
        <material name="body_gray"><color rgba="0.45 0.45 0.45 1"/></material>
      </visual>
      <collision>
        <geometry><box size="${base_length} ${base_width} ${base_height}"/></geometry>
      </collision>
      <xacro:box_inertia m="${base_mass}" x="${base_length}" y="${base_width}" z="${base_height}"/>
    </link>

    <!-- Wheel macro: cylinder about Y axis, inertia from wheel_mass/radius/width -->
    <xacro:macro name="wheel" params="name x y">
      <link name="${name}_link">
        <visual>
          <origin rpy="1.57079632679 0 0" xyz="0 0 0"/>
          <geometry><cylinder radius="${wheel_radius}" length="${wheel_width}"/></geometry>
          <material name="wheel_black"><color rgba="0.02 0.02 0.02 1"/></material>
        </visual>
        <collision>
          <origin rpy="1.57079632679 0 0" xyz="0 0 0"/>
          <geometry><cylinder radius="${wheel_radius}" length="${wheel_width}"/></geometry>
        </collision>
        <inertial>
          <mass value="${wheel_mass}"/>
          <inertia
            ixx="${(1.0/12.0)*wheel_mass*(3.0*wheel_radius*wheel_radius + wheel_width*wheel_width)}" ixy="0" ixz="0"
            iyy="${0.5*wheel_mass*wheel_radius*wheel_radius}" iyz="0"
            izz="${(1.0/12.0)*wheel_mass*(3.0*wheel_radius*wheel_radius + wheel_width*wheel_width)}"/>
        </inertial>
      </link>
      <joint name="${name}_joint" type="continuous">
        <parent link="base_link"/>
        <child link="${name}_link"/>
        <origin xyz="${x} ${y} ${wheel_z}" rpy="0 0 0"/>
        <axis xyz="0 1 0"/>
      </joint>
    </xacro:macro>

    <xacro:wheel name="left_front_wheel"  x="${wheel_x}"  y="${wheel_y}"/>
    <xacro:wheel name="left_rear_wheel"   x="${-wheel_x}" y="${wheel_y}"/>
    <xacro:wheel name="right_front_wheel" x="${wheel_x}"  y="${-wheel_y}"/>
    <xacro:wheel name="right_rear_wheel"  x="${-wheel_x}" y="${-wheel_y}"/>
  </xacro:macro>
</robot>
