<?xml version="1.0"?>
<robot xmlns:xacro="http://www.ros.org/wiki/xacro">
  <xacro:macro name="buddy_base">
    <link name="base_footprint"/>

    <joint name="base_footprint_joint" type="fixed">
      <parent link="base_footprint"/>
      <child link="base_link"/>
      <origin xyz="0 0 0.10" rpy="0 0 0"/>
    </joint>

    <link name="base_link">
      <visual>
        <geometry><box size="${base_length} ${base_width} ${base_height}"/></geometry>
      </visual>
      <collision>
        <geometry><box size="${base_length} ${base_width} ${base_height}"/></geometry>
      </collision>
      <inertial>
        <mass value="15.0"/>
        <!-- Placeholder inertia. Replace after chassis/mass distribution are known. -->
        <inertia ixx="0.30" ixy="0.0" ixz="0.0" iyy="0.45" iyz="0.0" izz="0.55"/>
      </inertial>
    </link>

    <xacro:macro name="wheel" params="name x y">
      <link name="${name}_link">
        <visual>
          <origin rpy="1.57079632679 0 0" xyz="0 0 0"/>
          <geometry><cylinder radius="${wheel_radius}" length="${wheel_width}"/></geometry>
        </visual>
        <collision>
          <origin rpy="1.57079632679 0 0" xyz="0 0 0"/>
          <geometry><cylinder radius="${wheel_radius}" length="${wheel_width}"/></geometry>
        </collision>
        <inertial>
          <mass value="0.8"/>
          <inertia ixx="0.003" ixy="0" ixz="0" iyy="0.003" iyz="0" izz="0.003"/>
        </inertial>
      </link>
      <joint name="${name}_joint" type="continuous">
        <parent link="base_link"/>
        <child link="${name}_link"/>
        <origin xyz="${x} ${y} ${wheel_z}" rpy="0 0 0"/>
        <axis xyz="0 1 0"/>
      </joint>
    </xacro:macro>

    <xacro:wheel name="left_front_wheel" x="${wheel_x}" y="${wheel_y}"/>
    <xacro:wheel name="left_rear_wheel" x="-${wheel_x}" y="${wheel_y}"/>
    <xacro:wheel name="right_front_wheel" x="${wheel_x}" y="-${wheel_y}"/>
    <xacro:wheel name="right_rear_wheel" x="-${wheel_x}" y="-${wheel_y}"/>
  </xacro:macro>
</robot>
